[2024-09-14T03:04:46.745+0000] {local_task_job_runner.py:123} INFO - ::group::Pre task execution logs
[2024-09-14T03:04:46.808+0000] {taskinstance.py:2603} INFO - Dependencies all met for dep_context=non-requeueable deps ti=<TaskInstance: dag_with_minio_s3_v1.sensor_minio_s3 scheduled__2024-09-13T00:00:00+00:00 [queued]>
[2024-09-14T03:04:46.838+0000] {taskinstance.py:2603} INFO - Dependencies all met for dep_context=requeueable deps ti=<TaskInstance: dag_with_minio_s3_v1.sensor_minio_s3 scheduled__2024-09-13T00:00:00+00:00 [queued]>
[2024-09-14T03:04:46.840+0000] {taskinstance.py:2856} INFO - Starting attempt 1 of 6
[2024-09-14T03:04:48.387+0000] {taskinstance.py:2879} INFO - Executing <Task(S3KeySensor): sensor_minio_s3> on 2024-09-13 00:00:00+00:00
[2024-09-14T03:04:48.413+0000] {logging_mixin.py:190} WARNING - /home/***/.local/lib/python3.12/site-packages/***/task/task_runner/standard_task_runner.py:70 DeprecationWarning: This process (pid=30508) is multi-threaded, use of fork() may lead to deadlocks in the child.
[2024-09-14T03:04:48.417+0000] {standard_task_runner.py:72} INFO - Started process 30565 to run task
[2024-09-14T03:04:48.410+0000] {standard_task_runner.py:104} INFO - Running: ['***', 'tasks', 'run', 'dag_with_minio_s3_v1', 'sensor_minio_s3', 'scheduled__2024-09-13T00:00:00+00:00', '--job-id', '617', '--raw', '--subdir', 'DAGS_FOLDER/minio_s3_dag.py', '--cfg-path', '/tmp/tmpg5fkr1k1']
[2024-09-14T03:04:48.427+0000] {standard_task_runner.py:105} INFO - Job 617: Subtask sensor_minio_s3
[2024-09-14T03:04:48.635+0000] {task_command.py:467} INFO - Running <TaskInstance: dag_with_minio_s3_v1.sensor_minio_s3 scheduled__2024-09-13T00:00:00+00:00 [running]> on host 01a3c7586b71
[2024-09-14T03:04:48.927+0000] {taskinstance.py:3122} INFO - Exporting env vars: AIRFLOW_CTX_DAG_OWNER='ubeyd' AIRFLOW_CTX_DAG_ID='dag_with_minio_s3_v1' AIRFLOW_CTX_TASK_ID='sensor_minio_s3' AIRFLOW_CTX_EXECUTION_DATE='2024-09-13T00:00:00+00:00' AIRFLOW_CTX_TRY_NUMBER='1' AIRFLOW_CTX_DAG_RUN_ID='scheduled__2024-09-13T00:00:00+00:00'
[2024-09-14T03:04:48.931+0000] {taskinstance.py:731} INFO - ::endgroup::
[2024-09-14T03:04:48.983+0000] {baseoperator.py:405} WARNING - S3KeySensor.execute cannot be called outside TaskInstance!
[2024-09-14T03:04:48.986+0000] {s3.py:118} INFO - Poking for key : s3://minio/data.csv
[2024-09-14T03:04:49.022+0000] {base.py:84} INFO - Retrieving connection 'minio_conn'
[2024-09-14T03:04:49.024+0000] {connection_wrapper.py:388} INFO - AWS Connection (conn_id='minio_conn', conn_type='aws') credentials retrieved from login and password.
[2024-09-14T03:04:49.029+0000] {logging_mixin.py:190} WARNING - <string>:9 AirflowProviderDeprecationWarning: extra['host'] is deprecated and will be removed in a future release. Please set extra['endpoint_url'] instead
[2024-09-14T03:04:55.816+0000] {taskinstance.py:3301} ERROR - Task failed with exception
Traceback (most recent call last):
  File "/home/airflow/.local/lib/python3.12/site-packages/urllib3/connection.py", line 196, in _new_conn
    sock = connection.create_connection(
           ^^^^^^^^^^^^^^^^^^^^^^^^^^^^^
  File "/home/airflow/.local/lib/python3.12/site-packages/urllib3/util/connection.py", line 85, in create_connection
    raise err
  File "/home/airflow/.local/lib/python3.12/site-packages/urllib3/util/connection.py", line 73, in create_connection
    sock.connect(sa)
OSError: [Errno 101] Network is unreachable

The above exception was the direct cause of the following exception:

Traceback (most recent call last):
  File "/home/airflow/.local/lib/python3.12/site-packages/botocore/httpsession.py", line 464, in send
    urllib_response = conn.urlopen(
                      ^^^^^^^^^^^^^
  File "/home/airflow/.local/lib/python3.12/site-packages/urllib3/connectionpool.py", line 843, in urlopen
    retries = retries.increment(
              ^^^^^^^^^^^^^^^^^^
  File "/home/airflow/.local/lib/python3.12/site-packages/urllib3/util/retry.py", line 449, in increment
    raise reraise(type(error), error, _stacktrace)
          ^^^^^^^^^^^^^^^^^^^^^^^^^^^^^^^^^^^^^^^^
  File "/home/airflow/.local/lib/python3.12/site-packages/urllib3/util/util.py", line 39, in reraise
    raise value
  File "/home/airflow/.local/lib/python3.12/site-packages/urllib3/connectionpool.py", line 789, in urlopen
    response = self._make_request(
               ^^^^^^^^^^^^^^^^^^^
  File "/home/airflow/.local/lib/python3.12/site-packages/urllib3/connectionpool.py", line 495, in _make_request
    conn.request(
  File "/home/airflow/.local/lib/python3.12/site-packages/botocore/awsrequest.py", line 96, in request
    rval = super().request(method, url, body, headers, *args, **kwargs)
           ^^^^^^^^^^^^^^^^^^^^^^^^^^^^^^^^^^^^^^^^^^^^^^^^^^^^^^^^^^^^
  File "/home/airflow/.local/lib/python3.12/site-packages/urllib3/connection.py", line 398, in request
    self.endheaders()
  File "/usr/local/lib/python3.12/http/client.py", line 1331, in endheaders
    self._send_output(message_body, encode_chunked=encode_chunked)
  File "/home/airflow/.local/lib/python3.12/site-packages/botocore/awsrequest.py", line 123, in _send_output
    self.send(msg)
  File "/home/airflow/.local/lib/python3.12/site-packages/botocore/awsrequest.py", line 223, in send
    return super().send(str)
           ^^^^^^^^^^^^^^^^^
  File "/usr/local/lib/python3.12/http/client.py", line 1035, in send
    self.connect()
  File "/home/airflow/.local/lib/python3.12/site-packages/urllib3/connection.py", line 236, in connect
    self.sock = self._new_conn()
                ^^^^^^^^^^^^^^^^
  File "/home/airflow/.local/lib/python3.12/site-packages/urllib3/connection.py", line 211, in _new_conn
    raise NewConnectionError(
urllib3.exceptions.NewConnectionError: <botocore.awsrequest.AWSHTTPConnection object at 0x7ff8ee689fd0>: Failed to establish a new connection: [Errno 101] Network is unreachable

During handling of the above exception, another exception occurred:

Traceback (most recent call last):
  File "/home/airflow/.local/lib/python3.12/site-packages/airflow/models/taskinstance.py", line 767, in _execute_task
    result = _execute_callable(context=context, **execute_callable_kwargs)
             ^^^^^^^^^^^^^^^^^^^^^^^^^^^^^^^^^^^^^^^^^^^^^^^^^^^^^^^^^^^^^
  File "/home/airflow/.local/lib/python3.12/site-packages/airflow/models/taskinstance.py", line 733, in _execute_callable
    return ExecutionCallableRunner(
           ^^^^^^^^^^^^^^^^^^^^^^^^
  File "/home/airflow/.local/lib/python3.12/site-packages/airflow/utils/operator_helpers.py", line 252, in run
    return self.func(*args, **kwargs)
           ^^^^^^^^^^^^^^^^^^^^^^^^^^
  File "/home/airflow/.local/lib/python3.12/site-packages/airflow/models/baseoperator.py", line 406, in wrapper
    return func(self, *args, **kwargs)
           ^^^^^^^^^^^^^^^^^^^^^^^^^^^
  File "/home/airflow/.local/lib/python3.12/site-packages/airflow/providers/amazon/aws/sensors/s3.py", line 189, in execute
    super().execute(context)
  File "/home/airflow/.local/lib/python3.12/site-packages/airflow/models/baseoperator.py", line 406, in wrapper
    return func(self, *args, **kwargs)
           ^^^^^^^^^^^^^^^^^^^^^^^^^^^
  File "/home/airflow/.local/lib/python3.12/site-packages/airflow/sensors/base.py", line 306, in execute
    raise e
  File "/home/airflow/.local/lib/python3.12/site-packages/airflow/sensors/base.py", line 286, in execute
    poke_return = self.poke(context)
                  ^^^^^^^^^^^^^^^^^^
  File "/home/airflow/.local/lib/python3.12/site-packages/airflow/providers/amazon/aws/sensors/s3.py", line 182, in poke
    return self._check_key(self.bucket_key, context=context)
           ^^^^^^^^^^^^^^^^^^^^^^^^^^^^^^^^^^^^^^^^^^^^^^^^^
  File "/home/airflow/.local/lib/python3.12/site-packages/airflow/providers/amazon/aws/sensors/s3.py", line 154, in _check_key
    obj = self.hook.head_object(key, bucket_name)
          ^^^^^^^^^^^^^^^^^^^^^^^^^^^^^^^^^^^^^^^
  File "/home/airflow/.local/lib/python3.12/site-packages/airflow/providers/amazon/aws/hooks/s3.py", line 158, in wrapper
    return func(*bound_args.args, **bound_args.kwargs)
           ^^^^^^^^^^^^^^^^^^^^^^^^^^^^^^^^^^^^^^^^^^^
  File "/home/airflow/.local/lib/python3.12/site-packages/airflow/providers/amazon/aws/hooks/s3.py", line 132, in wrapper
    return func(*bound_args.args, **bound_args.kwargs)
           ^^^^^^^^^^^^^^^^^^^^^^^^^^^^^^^^^^^^^^^^^^^
  File "/home/airflow/.local/lib/python3.12/site-packages/airflow/providers/amazon/aws/hooks/s3.py", line 919, in head_object
    return self.get_conn().head_object(Bucket=bucket_name, Key=key)
           ^^^^^^^^^^^^^^^^^^^^^^^^^^^^^^^^^^^^^^^^^^^^^^^^^^^^^^^^
  File "/home/airflow/.local/lib/python3.12/site-packages/botocore/client.py", line 565, in _api_call
    return self._make_api_call(operation_name, kwargs)
           ^^^^^^^^^^^^^^^^^^^^^^^^^^^^^^^^^^^^^^^^^^^
  File "/home/airflow/.local/lib/python3.12/site-packages/botocore/client.py", line 1001, in _make_api_call
    http, parsed_response = self._make_request(
                            ^^^^^^^^^^^^^^^^^^^
  File "/home/airflow/.local/lib/python3.12/site-packages/botocore/client.py", line 1027, in _make_request
    return self._endpoint.make_request(operation_model, request_dict)
           ^^^^^^^^^^^^^^^^^^^^^^^^^^^^^^^^^^^^^^^^^^^^^^^^^^^^^^^^^^
  File "/home/airflow/.local/lib/python3.12/site-packages/botocore/endpoint.py", line 119, in make_request
    return self._send_request(request_dict, operation_model)
           ^^^^^^^^^^^^^^^^^^^^^^^^^^^^^^^^^^^^^^^^^^^^^^^^^
  File "/home/airflow/.local/lib/python3.12/site-packages/botocore/endpoint.py", line 202, in _send_request
    while self._needs_retry(
          ^^^^^^^^^^^^^^^^^^
  File "/home/airflow/.local/lib/python3.12/site-packages/botocore/endpoint.py", line 354, in _needs_retry
    responses = self._event_emitter.emit(
                ^^^^^^^^^^^^^^^^^^^^^^^^^
  File "/home/airflow/.local/lib/python3.12/site-packages/botocore/hooks.py", line 412, in emit
    return self._emitter.emit(aliased_event_name, **kwargs)
           ^^^^^^^^^^^^^^^^^^^^^^^^^^^^^^^^^^^^^^^^^^^^^^^^
  File "/home/airflow/.local/lib/python3.12/site-packages/botocore/hooks.py", line 256, in emit
    return self._emit(event_name, kwargs)
           ^^^^^^^^^^^^^^^^^^^^^^^^^^^^^^
  File "/home/airflow/.local/lib/python3.12/site-packages/botocore/hooks.py", line 239, in _emit
    response = handler(**kwargs)
               ^^^^^^^^^^^^^^^^^
  File "/home/airflow/.local/lib/python3.12/site-packages/botocore/retryhandler.py", line 207, in __call__
    if self._checker(**checker_kwargs):
       ^^^^^^^^^^^^^^^^^^^^^^^^^^^^^^^
  File "/home/airflow/.local/lib/python3.12/site-packages/botocore/retryhandler.py", line 284, in __call__
    should_retry = self._should_retry(
                   ^^^^^^^^^^^^^^^^^^^
  File "/home/airflow/.local/lib/python3.12/site-packages/botocore/retryhandler.py", line 320, in _should_retry
    return self._checker(attempt_number, response, caught_exception)
           ^^^^^^^^^^^^^^^^^^^^^^^^^^^^^^^^^^^^^^^^^^^^^^^^^^^^^^^^^
  File "/home/airflow/.local/lib/python3.12/site-packages/botocore/retryhandler.py", line 363, in __call__
    checker_response = checker(
                       ^^^^^^^^
  File "/home/airflow/.local/lib/python3.12/site-packages/botocore/retryhandler.py", line 247, in __call__
    return self._check_caught_exception(
           ^^^^^^^^^^^^^^^^^^^^^^^^^^^^^
  File "/home/airflow/.local/lib/python3.12/site-packages/botocore/retryhandler.py", line 416, in _check_caught_exception
    raise caught_exception
  File "/home/airflow/.local/lib/python3.12/site-packages/botocore/endpoint.py", line 281, in _do_get_response
    http_response = self._send(request)
                    ^^^^^^^^^^^^^^^^^^^
  File "/home/airflow/.local/lib/python3.12/site-packages/botocore/endpoint.py", line 377, in _send
    return self.http_session.send(request)
           ^^^^^^^^^^^^^^^^^^^^^^^^^^^^^^^
  File "/home/airflow/.local/lib/python3.12/site-packages/botocore/httpsession.py", line 493, in send
    raise EndpointConnectionError(endpoint_url=request.url, error=e)
botocore.exceptions.EndpointConnectionError: Could not connect to the endpoint URL: "http://host.docker.internal:9000/minio/data.csv"
[2024-09-14T03:04:55.886+0000] {taskinstance.py:1225} INFO - Marking task as UP_FOR_RETRY. dag_id=dag_with_minio_s3_v1, task_id=sensor_minio_s3, run_id=scheduled__2024-09-13T00:00:00+00:00, execution_date=20240913T000000, start_date=20240914T030446, end_date=20240914T030455
[2024-09-14T03:04:56.167+0000] {taskinstance.py:340} INFO - ::group::Post task execution logs
[2024-09-14T03:04:56.168+0000] {standard_task_runner.py:124} ERROR - Failed to execute job 617 for task sensor_minio_s3 (Could not connect to the endpoint URL: "http://host.docker.internal:9000/minio/data.csv"; 30565)
Traceback (most recent call last):
  File "/home/airflow/.local/lib/python3.12/site-packages/urllib3/connection.py", line 196, in _new_conn
    sock = connection.create_connection(
           ^^^^^^^^^^^^^^^^^^^^^^^^^^^^^
  File "/home/airflow/.local/lib/python3.12/site-packages/urllib3/util/connection.py", line 85, in create_connection
    raise err
  File "/home/airflow/.local/lib/python3.12/site-packages/urllib3/util/connection.py", line 73, in create_connection
    sock.connect(sa)
OSError: [Errno 101] Network is unreachable

The above exception was the direct cause of the following exception:

Traceback (most recent call last):
  File "/home/airflow/.local/lib/python3.12/site-packages/botocore/httpsession.py", line 464, in send
    urllib_response = conn.urlopen(
                      ^^^^^^^^^^^^^
  File "/home/airflow/.local/lib/python3.12/site-packages/urllib3/connectionpool.py", line 843, in urlopen
    retries = retries.increment(
              ^^^^^^^^^^^^^^^^^^
  File "/home/airflow/.local/lib/python3.12/site-packages/urllib3/util/retry.py", line 449, in increment
    raise reraise(type(error), error, _stacktrace)
          ^^^^^^^^^^^^^^^^^^^^^^^^^^^^^^^^^^^^^^^^
  File "/home/airflow/.local/lib/python3.12/site-packages/urllib3/util/util.py", line 39, in reraise
    raise value
  File "/home/airflow/.local/lib/python3.12/site-packages/urllib3/connectionpool.py", line 789, in urlopen
    response = self._make_request(
               ^^^^^^^^^^^^^^^^^^^
  File "/home/airflow/.local/lib/python3.12/site-packages/urllib3/connectionpool.py", line 495, in _make_request
    conn.request(
  File "/home/airflow/.local/lib/python3.12/site-packages/botocore/awsrequest.py", line 96, in request
    rval = super().request(method, url, body, headers, *args, **kwargs)
           ^^^^^^^^^^^^^^^^^^^^^^^^^^^^^^^^^^^^^^^^^^^^^^^^^^^^^^^^^^^^
  File "/home/airflow/.local/lib/python3.12/site-packages/urllib3/connection.py", line 398, in request
    self.endheaders()
  File "/usr/local/lib/python3.12/http/client.py", line 1331, in endheaders
    self._send_output(message_body, encode_chunked=encode_chunked)
  File "/home/airflow/.local/lib/python3.12/site-packages/botocore/awsrequest.py", line 123, in _send_output
    self.send(msg)
  File "/home/airflow/.local/lib/python3.12/site-packages/botocore/awsrequest.py", line 223, in send
    return super().send(str)
           ^^^^^^^^^^^^^^^^^
  File "/usr/local/lib/python3.12/http/client.py", line 1035, in send
    self.connect()
  File "/home/airflow/.local/lib/python3.12/site-packages/urllib3/connection.py", line 236, in connect
    self.sock = self._new_conn()
                ^^^^^^^^^^^^^^^^
  File "/home/airflow/.local/lib/python3.12/site-packages/urllib3/connection.py", line 211, in _new_conn
    raise NewConnectionError(
urllib3.exceptions.NewConnectionError: <botocore.awsrequest.AWSHTTPConnection object at 0x7ff8ee689fd0>: Failed to establish a new connection: [Errno 101] Network is unreachable

During handling of the above exception, another exception occurred:

Traceback (most recent call last):
  File "/home/airflow/.local/lib/python3.12/site-packages/airflow/task/task_runner/standard_task_runner.py", line 117, in _start_by_fork
    ret = args.func(args, dag=self.dag)
          ^^^^^^^^^^^^^^^^^^^^^^^^^^^^^
  File "/home/airflow/.local/lib/python3.12/site-packages/airflow/cli/cli_config.py", line 49, in command
    return func(*args, **kwargs)
           ^^^^^^^^^^^^^^^^^^^^^
  File "/home/airflow/.local/lib/python3.12/site-packages/airflow/utils/cli.py", line 115, in wrapper
    return f(*args, **kwargs)
           ^^^^^^^^^^^^^^^^^^
  File "/home/airflow/.local/lib/python3.12/site-packages/airflow/cli/commands/task_command.py", line 483, in task_run
    task_return_code = _run_task_by_selected_method(args, _dag, ti)
                       ^^^^^^^^^^^^^^^^^^^^^^^^^^^^^^^^^^^^^^^^^^^^
  File "/home/airflow/.local/lib/python3.12/site-packages/airflow/cli/commands/task_command.py", line 256, in _run_task_by_selected_method
    return _run_raw_task(args, ti)
           ^^^^^^^^^^^^^^^^^^^^^^^
  File "/home/airflow/.local/lib/python3.12/site-packages/airflow/cli/commands/task_command.py", line 341, in _run_raw_task
    return ti._run_raw_task(
           ^^^^^^^^^^^^^^^^^
  File "/home/airflow/.local/lib/python3.12/site-packages/airflow/utils/session.py", line 97, in wrapper
    return func(*args, session=session, **kwargs)
           ^^^^^^^^^^^^^^^^^^^^^^^^^^^^^^^^^^^^^^
  File "/home/airflow/.local/lib/python3.12/site-packages/airflow/models/taskinstance.py", line 2995, in _run_raw_task
    return _run_raw_task(
           ^^^^^^^^^^^^^^
  File "/home/airflow/.local/lib/python3.12/site-packages/airflow/models/taskinstance.py", line 273, in _run_raw_task
    TaskInstance._execute_task_with_callbacks(
  File "/home/airflow/.local/lib/python3.12/site-packages/airflow/models/taskinstance.py", line 3149, in _execute_task_with_callbacks
    result = self._execute_task(context, task_orig)
             ^^^^^^^^^^^^^^^^^^^^^^^^^^^^^^^^^^^^^^
  File "/home/airflow/.local/lib/python3.12/site-packages/airflow/models/taskinstance.py", line 3173, in _execute_task
    return _execute_task(self, context, task_orig)
           ^^^^^^^^^^^^^^^^^^^^^^^^^^^^^^^^^^^^^^^
  File "/home/airflow/.local/lib/python3.12/site-packages/airflow/models/taskinstance.py", line 767, in _execute_task
    result = _execute_callable(context=context, **execute_callable_kwargs)
             ^^^^^^^^^^^^^^^^^^^^^^^^^^^^^^^^^^^^^^^^^^^^^^^^^^^^^^^^^^^^^
  File "/home/airflow/.local/lib/python3.12/site-packages/airflow/models/taskinstance.py", line 733, in _execute_callable
    return ExecutionCallableRunner(
           ^^^^^^^^^^^^^^^^^^^^^^^^
  File "/home/airflow/.local/lib/python3.12/site-packages/airflow/utils/operator_helpers.py", line 252, in run
    return self.func(*args, **kwargs)
           ^^^^^^^^^^^^^^^^^^^^^^^^^^
  File "/home/airflow/.local/lib/python3.12/site-packages/airflow/models/baseoperator.py", line 406, in wrapper
    return func(self, *args, **kwargs)
           ^^^^^^^^^^^^^^^^^^^^^^^^^^^
  File "/home/airflow/.local/lib/python3.12/site-packages/airflow/providers/amazon/aws/sensors/s3.py", line 189, in execute
    super().execute(context)
  File "/home/airflow/.local/lib/python3.12/site-packages/airflow/models/baseoperator.py", line 406, in wrapper
    return func(self, *args, **kwargs)
           ^^^^^^^^^^^^^^^^^^^^^^^^^^^
  File "/home/airflow/.local/lib/python3.12/site-packages/airflow/sensors/base.py", line 306, in execute
    raise e
  File "/home/airflow/.local/lib/python3.12/site-packages/airflow/sensors/base.py", line 286, in execute
    poke_return = self.poke(context)
                  ^^^^^^^^^^^^^^^^^^
  File "/home/airflow/.local/lib/python3.12/site-packages/airflow/providers/amazon/aws/sensors/s3.py", line 182, in poke
    return self._check_key(self.bucket_key, context=context)
           ^^^^^^^^^^^^^^^^^^^^^^^^^^^^^^^^^^^^^^^^^^^^^^^^^
  File "/home/airflow/.local/lib/python3.12/site-packages/airflow/providers/amazon/aws/sensors/s3.py", line 154, in _check_key
    obj = self.hook.head_object(key, bucket_name)
          ^^^^^^^^^^^^^^^^^^^^^^^^^^^^^^^^^^^^^^^
  File "/home/airflow/.local/lib/python3.12/site-packages/airflow/providers/amazon/aws/hooks/s3.py", line 158, in wrapper
    return func(*bound_args.args, **bound_args.kwargs)
           ^^^^^^^^^^^^^^^^^^^^^^^^^^^^^^^^^^^^^^^^^^^
  File "/home/airflow/.local/lib/python3.12/site-packages/airflow/providers/amazon/aws/hooks/s3.py", line 132, in wrapper
    return func(*bound_args.args, **bound_args.kwargs)
           ^^^^^^^^^^^^^^^^^^^^^^^^^^^^^^^^^^^^^^^^^^^
  File "/home/airflow/.local/lib/python3.12/site-packages/airflow/providers/amazon/aws/hooks/s3.py", line 919, in head_object
    return self.get_conn().head_object(Bucket=bucket_name, Key=key)
           ^^^^^^^^^^^^^^^^^^^^^^^^^^^^^^^^^^^^^^^^^^^^^^^^^^^^^^^^
  File "/home/airflow/.local/lib/python3.12/site-packages/botocore/client.py", line 565, in _api_call
    return self._make_api_call(operation_name, kwargs)
           ^^^^^^^^^^^^^^^^^^^^^^^^^^^^^^^^^^^^^^^^^^^
  File "/home/airflow/.local/lib/python3.12/site-packages/botocore/client.py", line 1001, in _make_api_call
    http, parsed_response = self._make_request(
                            ^^^^^^^^^^^^^^^^^^^
  File "/home/airflow/.local/lib/python3.12/site-packages/botocore/client.py", line 1027, in _make_request
    return self._endpoint.make_request(operation_model, request_dict)
           ^^^^^^^^^^^^^^^^^^^^^^^^^^^^^^^^^^^^^^^^^^^^^^^^^^^^^^^^^^
  File "/home/airflow/.local/lib/python3.12/site-packages/botocore/endpoint.py", line 119, in make_request
    return self._send_request(request_dict, operation_model)
           ^^^^^^^^^^^^^^^^^^^^^^^^^^^^^^^^^^^^^^^^^^^^^^^^^
  File "/home/airflow/.local/lib/python3.12/site-packages/botocore/endpoint.py", line 202, in _send_request
    while self._needs_retry(
          ^^^^^^^^^^^^^^^^^^
  File "/home/airflow/.local/lib/python3.12/site-packages/botocore/endpoint.py", line 354, in _needs_retry
    responses = self._event_emitter.emit(
                ^^^^^^^^^^^^^^^^^^^^^^^^^
  File "/home/airflow/.local/lib/python3.12/site-packages/botocore/hooks.py", line 412, in emit
    return self._emitter.emit(aliased_event_name, **kwargs)
           ^^^^^^^^^^^^^^^^^^^^^^^^^^^^^^^^^^^^^^^^^^^^^^^^
  File "/home/airflow/.local/lib/python3.12/site-packages/botocore/hooks.py", line 256, in emit
    return self._emit(event_name, kwargs)
           ^^^^^^^^^^^^^^^^^^^^^^^^^^^^^^
  File "/home/airflow/.local/lib/python3.12/site-packages/botocore/hooks.py", line 239, in _emit
    response = handler(**kwargs)
               ^^^^^^^^^^^^^^^^^
  File "/home/airflow/.local/lib/python3.12/site-packages/botocore/retryhandler.py", line 207, in __call__
    if self._checker(**checker_kwargs):
       ^^^^^^^^^^^^^^^^^^^^^^^^^^^^^^^
  File "/home/airflow/.local/lib/python3.12/site-packages/botocore/retryhandler.py", line 284, in __call__
    should_retry = self._should_retry(
                   ^^^^^^^^^^^^^^^^^^^
  File "/home/airflow/.local/lib/python3.12/site-packages/botocore/retryhandler.py", line 320, in _should_retry
    return self._checker(attempt_number, response, caught_exception)
           ^^^^^^^^^^^^^^^^^^^^^^^^^^^^^^^^^^^^^^^^^^^^^^^^^^^^^^^^^
  File "/home/airflow/.local/lib/python3.12/site-packages/botocore/retryhandler.py", line 363, in __call__
    checker_response = checker(
                       ^^^^^^^^
  File "/home/airflow/.local/lib/python3.12/site-packages/botocore/retryhandler.py", line 247, in __call__
    return self._check_caught_exception(
           ^^^^^^^^^^^^^^^^^^^^^^^^^^^^^
  File "/home/airflow/.local/lib/python3.12/site-packages/botocore/retryhandler.py", line 416, in _check_caught_exception
    raise caught_exception
  File "/home/airflow/.local/lib/python3.12/site-packages/botocore/endpoint.py", line 281, in _do_get_response
    http_response = self._send(request)
                    ^^^^^^^^^^^^^^^^^^^
  File "/home/airflow/.local/lib/python3.12/site-packages/botocore/endpoint.py", line 377, in _send
    return self.http_session.send(request)
           ^^^^^^^^^^^^^^^^^^^^^^^^^^^^^^^
  File "/home/airflow/.local/lib/python3.12/site-packages/botocore/httpsession.py", line 493, in send
    raise EndpointConnectionError(endpoint_url=request.url, error=e)
botocore.exceptions.EndpointConnectionError: Could not connect to the endpoint URL: "http://host.docker.internal:9000/minio/data.csv"
[2024-09-14T03:04:56.194+0000] {local_task_job_runner.py:261} INFO - Task exited with return code 1
[2024-09-14T03:04:56.213+0000] {taskinstance.py:3891} INFO - 0 downstream tasks scheduled from follow-on schedule check
[2024-09-14T03:04:56.217+0000] {local_task_job_runner.py:240} INFO - ::endgroup::
[2024-09-14T10:47:50.630+0000] {local_task_job_runner.py:123} INFO - ::group::Pre task execution logs
[2024-09-14T10:47:51.409+0000] {taskinstance.py:2603} INFO - Dependencies all met for dep_context=non-requeueable deps ti=<TaskInstance: dag_with_minio_s3_v1.sensor_minio_s3 scheduled__2024-09-13T00:00:00+00:00 [queued]>
[2024-09-14T10:47:51.571+0000] {taskinstance.py:2603} INFO - Dependencies all met for dep_context=requeueable deps ti=<TaskInstance: dag_with_minio_s3_v1.sensor_minio_s3 scheduled__2024-09-13T00:00:00+00:00 [queued]>
[2024-09-14T10:47:51.572+0000] {taskinstance.py:2856} INFO - Starting attempt 1 of 6
[2024-09-14T10:47:53.879+0000] {taskinstance.py:2879} INFO - Executing <Task(S3KeySensor): sensor_minio_s3> on 2024-09-13 00:00:00+00:00
[2024-09-14T10:47:53.901+0000] {logging_mixin.py:190} WARNING - /home/***/.local/lib/python3.12/site-packages/***/task/task_runner/standard_task_runner.py:70 DeprecationWarning: This process (pid=48965) is multi-threaded, use of fork() may lead to deadlocks in the child.
[2024-09-14T10:47:53.902+0000] {standard_task_runner.py:72} INFO - Started process 48989 to run task
[2024-09-14T10:47:53.902+0000] {standard_task_runner.py:104} INFO - Running: ['***', 'tasks', 'run', 'dag_with_minio_s3_v1', 'sensor_minio_s3', 'scheduled__2024-09-13T00:00:00+00:00', '--job-id', '644', '--raw', '--subdir', 'DAGS_FOLDER/minio_s3_dag.py', '--cfg-path', '/tmp/tmpnfm67gl6']
[2024-09-14T10:47:53.903+0000] {standard_task_runner.py:105} INFO - Job 644: Subtask sensor_minio_s3
[2024-09-14T10:47:54.003+0000] {task_command.py:467} INFO - Running <TaskInstance: dag_with_minio_s3_v1.sensor_minio_s3 scheduled__2024-09-13T00:00:00+00:00 [running]> on host 01a3c7586b71
[2024-09-14T10:47:54.131+0000] {taskinstance.py:3122} INFO - Exporting env vars: AIRFLOW_CTX_DAG_OWNER='ubeyd' AIRFLOW_CTX_DAG_ID='dag_with_minio_s3_v1' AIRFLOW_CTX_TASK_ID='sensor_minio_s3' AIRFLOW_CTX_EXECUTION_DATE='2024-09-13T00:00:00+00:00' AIRFLOW_CTX_TRY_NUMBER='1' AIRFLOW_CTX_DAG_RUN_ID='scheduled__2024-09-13T00:00:00+00:00'
[2024-09-14T10:47:54.133+0000] {taskinstance.py:731} INFO - ::endgroup::
[2024-09-14T10:47:54.155+0000] {baseoperator.py:405} WARNING - S3KeySensor.execute cannot be called outside TaskInstance!
[2024-09-14T10:47:54.156+0000] {s3.py:118} INFO - Poking for key : s3://***/data.csv
[2024-09-14T10:47:54.170+0000] {base.py:84} INFO - Retrieving connection 'minio_conn'
[2024-09-14T10:47:54.171+0000] {connection_wrapper.py:388} INFO - AWS Connection (conn_id='minio_conn', conn_type='aws') credentials retrieved from login and password.
[2024-09-14T10:47:54.174+0000] {logging_mixin.py:190} WARNING - <string>:9 AirflowProviderDeprecationWarning: extra['host'] is deprecated and will be removed in a future release. Please set extra['endpoint_url'] instead
[2024-09-14T10:47:54.625+0000] {taskinstance.py:3301} ERROR - Task failed with exception
Traceback (most recent call last):
  File "/home/airflow/.local/lib/python3.12/site-packages/airflow/models/taskinstance.py", line 767, in _execute_task
    result = _execute_callable(context=context, **execute_callable_kwargs)
             ^^^^^^^^^^^^^^^^^^^^^^^^^^^^^^^^^^^^^^^^^^^^^^^^^^^^^^^^^^^^^
  File "/home/airflow/.local/lib/python3.12/site-packages/airflow/models/taskinstance.py", line 733, in _execute_callable
    return ExecutionCallableRunner(
           ^^^^^^^^^^^^^^^^^^^^^^^^
  File "/home/airflow/.local/lib/python3.12/site-packages/airflow/utils/operator_helpers.py", line 252, in run
    return self.func(*args, **kwargs)
           ^^^^^^^^^^^^^^^^^^^^^^^^^^
  File "/home/airflow/.local/lib/python3.12/site-packages/airflow/models/baseoperator.py", line 406, in wrapper
    return func(self, *args, **kwargs)
           ^^^^^^^^^^^^^^^^^^^^^^^^^^^
  File "/home/airflow/.local/lib/python3.12/site-packages/airflow/providers/amazon/aws/sensors/s3.py", line 189, in execute
    super().execute(context)
  File "/home/airflow/.local/lib/python3.12/site-packages/airflow/models/baseoperator.py", line 406, in wrapper
    return func(self, *args, **kwargs)
           ^^^^^^^^^^^^^^^^^^^^^^^^^^^
  File "/home/airflow/.local/lib/python3.12/site-packages/airflow/sensors/base.py", line 306, in execute
    raise e
  File "/home/airflow/.local/lib/python3.12/site-packages/airflow/sensors/base.py", line 286, in execute
    poke_return = self.poke(context)
                  ^^^^^^^^^^^^^^^^^^
  File "/home/airflow/.local/lib/python3.12/site-packages/airflow/providers/amazon/aws/sensors/s3.py", line 182, in poke
    return self._check_key(self.bucket_key, context=context)
           ^^^^^^^^^^^^^^^^^^^^^^^^^^^^^^^^^^^^^^^^^^^^^^^^^
  File "/home/airflow/.local/lib/python3.12/site-packages/airflow/providers/amazon/aws/sensors/s3.py", line 154, in _check_key
    obj = self.hook.head_object(key, bucket_name)
          ^^^^^^^^^^^^^^^^^^^^^^^^^^^^^^^^^^^^^^^
  File "/home/airflow/.local/lib/python3.12/site-packages/airflow/providers/amazon/aws/hooks/s3.py", line 158, in wrapper
    return func(*bound_args.args, **bound_args.kwargs)
           ^^^^^^^^^^^^^^^^^^^^^^^^^^^^^^^^^^^^^^^^^^^
  File "/home/airflow/.local/lib/python3.12/site-packages/airflow/providers/amazon/aws/hooks/s3.py", line 132, in wrapper
    return func(*bound_args.args, **bound_args.kwargs)
           ^^^^^^^^^^^^^^^^^^^^^^^^^^^^^^^^^^^^^^^^^^^
  File "/home/airflow/.local/lib/python3.12/site-packages/airflow/providers/amazon/aws/hooks/s3.py", line 924, in head_object
    raise e
  File "/home/airflow/.local/lib/python3.12/site-packages/airflow/providers/amazon/aws/hooks/s3.py", line 919, in head_object
    return self.get_conn().head_object(Bucket=bucket_name, Key=key)
           ^^^^^^^^^^^^^^^^^^^^^^^^^^^^^^^^^^^^^^^^^^^^^^^^^^^^^^^^
  File "/home/airflow/.local/lib/python3.12/site-packages/botocore/client.py", line 565, in _api_call
    return self._make_api_call(operation_name, kwargs)
           ^^^^^^^^^^^^^^^^^^^^^^^^^^^^^^^^^^^^^^^^^^^
  File "/home/airflow/.local/lib/python3.12/site-packages/botocore/client.py", line 1021, in _make_api_call
    raise error_class(parsed_response, operation_name)
botocore.exceptions.ClientError: An error occurred (403) when calling the HeadObject operation: Forbidden
[2024-09-14T10:47:54.662+0000] {taskinstance.py:1225} INFO - Marking task as UP_FOR_RETRY. dag_id=dag_with_minio_s3_v1, task_id=sensor_minio_s3, run_id=scheduled__2024-09-13T00:00:00+00:00, execution_date=20240913T000000, start_date=20240914T104751, end_date=20240914T104754
[2024-09-14T10:47:54.683+0000] {taskinstance.py:340} INFO - ::group::Post task execution logs
[2024-09-14T10:47:54.684+0000] {standard_task_runner.py:124} ERROR - Failed to execute job 644 for task sensor_minio_s3 (An error occurred (403) when calling the HeadObject operation: Forbidden; 48989)
Traceback (most recent call last):
  File "/home/airflow/.local/lib/python3.12/site-packages/airflow/task/task_runner/standard_task_runner.py", line 117, in _start_by_fork
    ret = args.func(args, dag=self.dag)
          ^^^^^^^^^^^^^^^^^^^^^^^^^^^^^
  File "/home/airflow/.local/lib/python3.12/site-packages/airflow/cli/cli_config.py", line 49, in command
    return func(*args, **kwargs)
           ^^^^^^^^^^^^^^^^^^^^^
  File "/home/airflow/.local/lib/python3.12/site-packages/airflow/utils/cli.py", line 115, in wrapper
    return f(*args, **kwargs)
           ^^^^^^^^^^^^^^^^^^
  File "/home/airflow/.local/lib/python3.12/site-packages/airflow/cli/commands/task_command.py", line 483, in task_run
    task_return_code = _run_task_by_selected_method(args, _dag, ti)
                       ^^^^^^^^^^^^^^^^^^^^^^^^^^^^^^^^^^^^^^^^^^^^
  File "/home/airflow/.local/lib/python3.12/site-packages/airflow/cli/commands/task_command.py", line 256, in _run_task_by_selected_method
    return _run_raw_task(args, ti)
           ^^^^^^^^^^^^^^^^^^^^^^^
  File "/home/airflow/.local/lib/python3.12/site-packages/airflow/cli/commands/task_command.py", line 341, in _run_raw_task
    return ti._run_raw_task(
           ^^^^^^^^^^^^^^^^^
  File "/home/airflow/.local/lib/python3.12/site-packages/airflow/utils/session.py", line 97, in wrapper
    return func(*args, session=session, **kwargs)
           ^^^^^^^^^^^^^^^^^^^^^^^^^^^^^^^^^^^^^^
  File "/home/airflow/.local/lib/python3.12/site-packages/airflow/models/taskinstance.py", line 2995, in _run_raw_task
    return _run_raw_task(
           ^^^^^^^^^^^^^^
  File "/home/airflow/.local/lib/python3.12/site-packages/airflow/models/taskinstance.py", line 273, in _run_raw_task
    TaskInstance._execute_task_with_callbacks(
  File "/home/airflow/.local/lib/python3.12/site-packages/airflow/models/taskinstance.py", line 3149, in _execute_task_with_callbacks
    result = self._execute_task(context, task_orig)
             ^^^^^^^^^^^^^^^^^^^^^^^^^^^^^^^^^^^^^^
  File "/home/airflow/.local/lib/python3.12/site-packages/airflow/models/taskinstance.py", line 3173, in _execute_task
    return _execute_task(self, context, task_orig)
           ^^^^^^^^^^^^^^^^^^^^^^^^^^^^^^^^^^^^^^^
  File "/home/airflow/.local/lib/python3.12/site-packages/airflow/models/taskinstance.py", line 767, in _execute_task
    result = _execute_callable(context=context, **execute_callable_kwargs)
             ^^^^^^^^^^^^^^^^^^^^^^^^^^^^^^^^^^^^^^^^^^^^^^^^^^^^^^^^^^^^^
  File "/home/airflow/.local/lib/python3.12/site-packages/airflow/models/taskinstance.py", line 733, in _execute_callable
    return ExecutionCallableRunner(
           ^^^^^^^^^^^^^^^^^^^^^^^^
  File "/home/airflow/.local/lib/python3.12/site-packages/airflow/utils/operator_helpers.py", line 252, in run
    return self.func(*args, **kwargs)
           ^^^^^^^^^^^^^^^^^^^^^^^^^^
  File "/home/airflow/.local/lib/python3.12/site-packages/airflow/models/baseoperator.py", line 406, in wrapper
    return func(self, *args, **kwargs)
           ^^^^^^^^^^^^^^^^^^^^^^^^^^^
  File "/home/airflow/.local/lib/python3.12/site-packages/airflow/providers/amazon/aws/sensors/s3.py", line 189, in execute
    super().execute(context)
  File "/home/airflow/.local/lib/python3.12/site-packages/airflow/models/baseoperator.py", line 406, in wrapper
    return func(self, *args, **kwargs)
           ^^^^^^^^^^^^^^^^^^^^^^^^^^^
  File "/home/airflow/.local/lib/python3.12/site-packages/airflow/sensors/base.py", line 306, in execute
    raise e
  File "/home/airflow/.local/lib/python3.12/site-packages/airflow/sensors/base.py", line 286, in execute
    poke_return = self.poke(context)
                  ^^^^^^^^^^^^^^^^^^
  File "/home/airflow/.local/lib/python3.12/site-packages/airflow/providers/amazon/aws/sensors/s3.py", line 182, in poke
    return self._check_key(self.bucket_key, context=context)
           ^^^^^^^^^^^^^^^^^^^^^^^^^^^^^^^^^^^^^^^^^^^^^^^^^
  File "/home/airflow/.local/lib/python3.12/site-packages/airflow/providers/amazon/aws/sensors/s3.py", line 154, in _check_key
    obj = self.hook.head_object(key, bucket_name)
          ^^^^^^^^^^^^^^^^^^^^^^^^^^^^^^^^^^^^^^^
  File "/home/airflow/.local/lib/python3.12/site-packages/airflow/providers/amazon/aws/hooks/s3.py", line 158, in wrapper
    return func(*bound_args.args, **bound_args.kwargs)
           ^^^^^^^^^^^^^^^^^^^^^^^^^^^^^^^^^^^^^^^^^^^
  File "/home/airflow/.local/lib/python3.12/site-packages/airflow/providers/amazon/aws/hooks/s3.py", line 132, in wrapper
    return func(*bound_args.args, **bound_args.kwargs)
           ^^^^^^^^^^^^^^^^^^^^^^^^^^^^^^^^^^^^^^^^^^^
  File "/home/airflow/.local/lib/python3.12/site-packages/airflow/providers/amazon/aws/hooks/s3.py", line 924, in head_object
    raise e
  File "/home/airflow/.local/lib/python3.12/site-packages/airflow/providers/amazon/aws/hooks/s3.py", line 919, in head_object
    return self.get_conn().head_object(Bucket=bucket_name, Key=key)
           ^^^^^^^^^^^^^^^^^^^^^^^^^^^^^^^^^^^^^^^^^^^^^^^^^^^^^^^^
  File "/home/airflow/.local/lib/python3.12/site-packages/botocore/client.py", line 565, in _api_call
    return self._make_api_call(operation_name, kwargs)
           ^^^^^^^^^^^^^^^^^^^^^^^^^^^^^^^^^^^^^^^^^^^
  File "/home/airflow/.local/lib/python3.12/site-packages/botocore/client.py", line 1021, in _make_api_call
    raise error_class(parsed_response, operation_name)
botocore.exceptions.ClientError: An error occurred (403) when calling the HeadObject operation: Forbidden
[2024-09-14T10:47:54.723+0000] {local_task_job_runner.py:261} INFO - Task exited with return code 1
[2024-09-14T10:47:54.745+0000] {taskinstance.py:3891} INFO - 0 downstream tasks scheduled from follow-on schedule check
[2024-09-14T10:47:54.748+0000] {local_task_job_runner.py:240} INFO - ::endgroup::
[2024-09-14T12:34:28.978+0000] {local_task_job_runner.py:123} INFO - ::group::Pre task execution logs
[2024-09-14T12:34:29.009+0000] {taskinstance.py:2603} INFO - Dependencies all met for dep_context=non-requeueable deps ti=<TaskInstance: dag_with_minio_s3_v1.sensor_minio_s3 scheduled__2024-09-13T00:00:00+00:00 [queued]>
[2024-09-14T12:34:29.021+0000] {taskinstance.py:2603} INFO - Dependencies all met for dep_context=requeueable deps ti=<TaskInstance: dag_with_minio_s3_v1.sensor_minio_s3 scheduled__2024-09-13T00:00:00+00:00 [queued]>
[2024-09-14T12:34:29.022+0000] {taskinstance.py:2856} INFO - Starting attempt 1 of 6
[2024-09-14T12:34:29.293+0000] {taskinstance.py:2879} INFO - Executing <Task(S3KeySensor): sensor_minio_s3> on 2024-09-13 00:00:00+00:00
[2024-09-14T12:34:29.325+0000] {logging_mixin.py:190} WARNING - /home/***/.local/lib/python3.12/site-packages/***/task/task_runner/standard_task_runner.py:70 DeprecationWarning: This process (pid=56871) is multi-threaded, use of fork() may lead to deadlocks in the child.
[2024-09-14T12:34:29.327+0000] {standard_task_runner.py:104} INFO - Running: ['***', 'tasks', 'run', 'dag_with_minio_s3_v1', 'sensor_minio_s3', 'scheduled__2024-09-13T00:00:00+00:00', '--job-id', '729', '--raw', '--subdir', 'DAGS_FOLDER/minio_s3_dag.py', '--cfg-path', '/tmp/tmp0qh02tpk']
[2024-09-14T12:34:29.335+0000] {standard_task_runner.py:72} INFO - Started process 56884 to run task
[2024-09-14T12:34:29.338+0000] {standard_task_runner.py:105} INFO - Job 729: Subtask sensor_minio_s3
[2024-09-14T12:34:29.441+0000] {task_command.py:467} INFO - Running <TaskInstance: dag_with_minio_s3_v1.sensor_minio_s3 scheduled__2024-09-13T00:00:00+00:00 [running]> on host 01a3c7586b71
[2024-09-14T12:34:29.567+0000] {taskinstance.py:3122} INFO - Exporting env vars: AIRFLOW_CTX_DAG_OWNER='ubeyd' AIRFLOW_CTX_DAG_ID='dag_with_minio_s3_v1' AIRFLOW_CTX_TASK_ID='sensor_minio_s3' AIRFLOW_CTX_EXECUTION_DATE='2024-09-13T00:00:00+00:00' AIRFLOW_CTX_TRY_NUMBER='1' AIRFLOW_CTX_DAG_RUN_ID='scheduled__2024-09-13T00:00:00+00:00'
[2024-09-14T12:34:29.568+0000] {taskinstance.py:731} INFO - ::endgroup::
[2024-09-14T12:34:29.590+0000] {baseoperator.py:405} WARNING - S3KeySensor.execute cannot be called outside TaskInstance!
[2024-09-14T12:34:29.591+0000] {s3.py:118} INFO - Poking for key : s3://***/data.csv
[2024-09-14T12:34:29.604+0000] {base.py:84} INFO - Retrieving connection 'minio_conn'
[2024-09-14T12:34:29.605+0000] {connection_wrapper.py:388} INFO - AWS Connection (conn_id='minio_conn', conn_type='aws') credentials retrieved from login and password.
[2024-09-14T12:34:29.608+0000] {logging_mixin.py:190} WARNING - <string>:9 AirflowProviderDeprecationWarning: extra['host'] is deprecated and will be removed in a future release. Please set extra['endpoint_url'] instead
[2024-09-14T12:34:30.050+0000] {base.py:336} INFO - Success criteria met. Exiting.
[2024-09-14T12:34:30.060+0000] {taskinstance.py:340} INFO - ::group::Post task execution logs
[2024-09-14T12:34:30.061+0000] {taskinstance.py:352} INFO - Marking task as SUCCESS. dag_id=dag_with_minio_s3_v1, task_id=sensor_minio_s3, run_id=scheduled__2024-09-13T00:00:00+00:00, execution_date=20240913T000000, start_date=20240914T123429, end_date=20240914T123430
[2024-09-14T12:34:30.133+0000] {local_task_job_runner.py:261} INFO - Task exited with return code 0
[2024-09-14T12:34:30.153+0000] {taskinstance.py:3891} INFO - 0 downstream tasks scheduled from follow-on schedule check
[2024-09-14T12:34:30.157+0000] {local_task_job_runner.py:240} INFO - ::endgroup::
